<?xml version="1.0"?>

<robot xmlns:xacro="http://www.ros.org/wiki/xacro"
       name="simple_robot">

  <xacro:property name="chassis_length" value="0.4"/>
  <xacro:property name="chassis_width" value="0.3"/>
  <xacro:property name="chassis_height" value="0.1"/>

  <xacro:property name="wheel_radius" value="0.05"/>
  <xacro:property name="wheel_width" value="0.03"/>

  <!-- Chassis -->

  <link name="base_link">

    <visual>
      <geometry>
        <box size="${chassis_length}
                   ${chassis_width}
                   ${chassis_height}"/>
      </geometry>
    </visual>

  </link>

  <!-- Left Wheel -->

  <link name="left_wheel">

    <visual>
      <geometry>
        <cylinder radius="${wheel_radius}"
                  length="${wheel_width}"/>
      </geometry>
    </visual>

  </link>

  <!-- Right Wheel -->

  <link name="right_wheel">

    <visual>
      <geometry>
        <cylinder radius="${wheel_radius}"
                  length="${wheel_width}"/>
      </geometry>
    </visual>

  </link>

  <!-- Joints -->

  <joint name="left_wheel_joint"
         type="continuous">

      <parent link="base_link"/>
      <child link="left_wheel"/>

      <origin xyz="0 0.15 0"
              rpy="1.5708 0 0"/>

      <axis xyz="0 0 1"/>

  </joint>

  <joint name="right_wheel_joint"
         type="continuous">

      <parent link="base_link"/>
      <child link="right_wheel"/>

      <origin xyz="0 -0.15 0"
              rpy="1.5708 0 0"/>

      <axis xyz="0 0 1"/>

  </joint>

</robot>
