<?xml version="1.0"?>

<robot xmlns:xacro="http://www.ros.org/wiki/xacro">

<xacro:macro name="wheel"
params="name x y z radius width">

<link name="${name}_link">

  <visual>
    <origin xyz="0 0 0" rpy="1.5708 0 0"/>
    <geometry>
      <cylinder radius="${radius}" length="${width}"/>
    </geometry>
  </visual>

  <collision>
    <origin xyz="0 0 0" rpy="1.5708 0 0"/>
    <geometry>
      <cylinder radius="${radius}" length="${width}"/>
    </geometry>
  </collision>

  <inertial>
    <mass value="0.5"/>
    <origin xyz="0 0 0"/>
    <inertia ixx="0.001" iyy="0.001" izz="0.001"
             ixy="0" ixz="0" iyz="0"/>
  </inertial>

</link>

<joint name="${name}_joint"
       type="continuous">

  <parent link="base_link"/>
  <child link="${name}_link"/>

  <origin xyz="${x} ${y} ${z}"/>

  <axis xyz="0 1 0"/>

  <limit effort="20"
         velocity="50"/>

</joint>

</xacro:macro>

</robot>
